2025-05-10 08:46:26,596 - INFO - Connecting to map hub
2025-05-10 08:46:27,704 - INFO - Connection successful
2025-05-10 08:46:27,704 - INFO - Connecting to object storage
2025-05-10 08:47:11,854 - INFO - Downloading photos on the traps layer
2025-05-10 08:47:25,666 - INFO - Downloading photos on the trap checks layer
2025-05-10 08:47:47,618 - INFO - Downloading photos on the fisher layer
2025-05-10 08:47:52,660 - INFO - Creating report
2025-05-10 08:47:52,662 - INFO - Generating traps sheet
2025-05-10 08:47:53,265 - INFO - Generating trap checks sheet
2025-05-10 08:47:53,787 - INFO - Generating fisher sheet
2025-05-10 08:47:54,160 - INFO - Uploading document to object storage
2025-05-10 08:47:54,388 - ERROR - There was an exception
Traceback (most recent call last):
  File "/usr/share/miniconda/envs/trapper_env/lib/python3.9/site-packages/boto3/s3/transfer.py", line 372, in upload_file
    future.result()
  File "/usr/share/miniconda/envs/trapper_env/lib/python3.9/site-packages/s3transfer/futures.py", line 103, in result
    return self._coordinator.result()
  File "/usr/share/miniconda/envs/trapper_env/lib/python3.9/site-packages/s3transfer/futures.py", line 264, in result
    raise self._exception
  File "/usr/share/miniconda/envs/trapper_env/lib/python3.9/site-packages/s3transfer/tasks.py", line 135, in __call__
    return self._execute_main(kwargs)
  File "/usr/share/miniconda/envs/trapper_env/lib/python3.9/site-packages/s3transfer/tasks.py", line 158, in _execute_main
    return_value = self._main(**kwargs)
  File "/usr/share/miniconda/envs/trapper_env/lib/python3.9/site-packages/s3transfer/upload.py", line 796, in _main
    client.put_object(Bucket=bucket, Key=key, Body=body, **extra_args)
  File "/usr/share/miniconda/envs/trapper_env/lib/python3.9/site-packages/botocore/client.py", line 570, in _api_call
    return self._make_api_call(operation_name, kwargs)
  File "/usr/share/miniconda/envs/trapper_env/lib/python3.9/site-packages/botocore/context.py", line 124, in wrapper
    return func(*args, **kwargs)
  File "/usr/share/miniconda/envs/trapper_env/lib/python3.9/site-packages/botocore/client.py", line 1031, in _make_api_call
    raise error_class(parsed_response, operation_name)
botocore.exceptions.ClientError: An error occurred (XAmzContentSHA256Mismatch) when calling the PutObject operation: The Content-SHA256 you specified did not match what we received

During handling of the above exception, another exception occurred:

Traceback (most recent call last):
  File "/home/runner/work/trapper-data-reporting/trapper-data-reporting/trapper_data_collection/trapper_reporting.py", line 27, in run_app
    report.create_excel()
  File "/home/runner/work/trapper-data-reporting/trapper-data-reporting/trapper_data_collection/trapper_reporting.py", line 340, in create_excel
    self.boto_resource.meta.client.upload_file(xl_report, self.trapper_bucket, ostore_path)
  File "/usr/share/miniconda/envs/trapper_env/lib/python3.9/site-packages/botocore/context.py", line 124, in wrapper
    return func(*args, **kwargs)
  File "/usr/share/miniconda/envs/trapper_env/lib/python3.9/site-packages/boto3/s3/inject.py", line 170, in upload_file
    return transfer.upload_file(
  File "/usr/share/miniconda/envs/trapper_env/lib/python3.9/site-packages/boto3/s3/transfer.py", line 378, in upload_file
    raise S3UploadFailedError(
boto3.exceptions.S3UploadFailedError: Failed to upload trapper_data_report.xlsx to fishes/trapper_data_collection/trapper_data_report.xlsx: An error occurred (XAmzContentSHA256Mismatch) when calling the PutObject operation: The Content-SHA256 you specified did not match what we received
2025-05-10 08:47:54,461 - INFO - Disconnecting from maphub
2025-05-10 08:47:54,462 - INFO - Closing object storage connection
