2025-03-03 08:31:18,619 - INFO - Connecting to map hub
2025-03-03 08:31:20,069 - INFO - Connection successful
2025-03-03 08:31:20,069 - INFO - Shifting any traps that indicated the coordinates should not be included
2025-03-03 08:31:21,606 - INFO - Updating traps layer with most recent trap check status
2025-03-03 08:31:34,449 - INFO - Renaming photos on the traps layer
2025-03-03 08:31:52,943 - INFO - Renaming photos on the trap checks layer
2025-03-03 08:32:26,151 - INFO - Renaming photos on the fisher layer
2025-03-03 08:32:33,278 - INFO - Renaming IMG_3266.jpeg to fisher_kill site/fisher carcass_109_photo1.jpeg
2025-03-03 08:32:33,740 - ERROR - There was an exception
Traceback (most recent call last):
  File "/home/runner/work/trapper-data-reporting/trapper-data-reporting/trapper_data_collection/trapper_data_modification.py", line 20, in run_app
    traps.update_attachments()
  File "/home/runner/work/trapper-data-reporting/trapper-data-reporting/trapper_data_collection/trapper_data_modification.py", line 172, in update_attachments
    self.rename_attachments(ago_layer=self.ago_fisher, layer_name='fisher', fld_unique_id='OBJECTID', fld_picture='PICTURE', photo_prefix='fisher')
  File "/home/runner/work/trapper-data-reporting/trapper-data-reporting/trapper_data_collection/trapper_data_modification.py", line 241, in rename_attachments
    os.rename(attach_file, new_attach_file)
FileNotFoundError: [Errno 2] No such file or directory: '/tmp/IMG_3266.jpeg' -> '/tmp/fisher_kill site/fisher carcass_109_photo1.jpeg'
2025-03-03 08:32:33,740 - INFO - Disconnecting from maphub
