2024-11-12 21:45:56,250 - ERROR - There was an exception
Traceback (most recent call last):
  File "/home/runner/work/trapper-data-reporting/trapper-data-reporting/trapper_data_collection/trapper_reporting.py", line 23, in run_app
    report = TrapReport(ago_user=ago_user, ago_pass=ago_pass, obj_store_user=obj_store_user,
  File "/home/runner/work/trapper-data-reporting/trapper-data-reporting/trapper_data_collection/trapper_reporting.py", line 91, in __init__
    self.dict_traplines = defaultdict(Trapline)
NameError: name 'Trapline' is not defined
2024-11-12 21:45:56,251 - INFO - Disconnecting from maphub
